<?xml version="1.0" encoding="utf-8"?>
<!-- This URDF was automatically created by SolidWorks to URDF Exporter! Originally created by Stephen Brawner (brawner@gmail.com) 
     Commit Version: 1.6.0-4-g7f85cfe  Build Version: 1.6.7995.38578
     For more information, please see http://wiki.ros.org/sw_urdf_exporter -->
<robot
  name="scara">
  <link
    name="base_link">
    <inertial>
      <origin
        xyz="4.9228E-19 0.057416 0.00026601"
        rpy="0 0 0" />
      <mass
        value="1.2659" />
      <inertia
        ixx="0.0041167"
        ixy="1.7022E-19"
        ixz="-1.4674E-19"
        iyy="0.0027026"
        iyz="-2.6126E-05"
        izz="0.0031757" />
    </inertial>
    <visual>
      <origin
        xyz="0 0 0"
        rpy="0 0 0" />
      <geometry>
        <mesh
          filename="package://scara/meshes/base_link.STL" />
      </geometry>
      <material
        name="">
        <color
          rgba="0.79216 0.81961 0.93333 1" />
      </material>
    </visual>
    <collision>
      <origin
        xyz="0 0 0"
        rpy="0 0 0" />
      <geometry>
        <mesh
          filename="package://scara/meshes/base_link.STL" />
      </geometry>
    </collision>
  </link>
  <link
    name="L1">
    <inertial>
      <origin
        xyz="0.067038 0.023797 -3.8903E-18"
        rpy="0 0 0" />
      <mass
        value="0.23993" />
      <inertia
        ixx="5.7474E-05"
        ixy="-5.325E-06"
        ixz="3.6951E-20"
        iyy="0.00068723"
        iyz="-2.0839E-21"
        izz="0.00066974" />
    </inertial>
    <visual>
      <origin
        xyz="0 0 0"
        rpy="0 0 0" />
      <geometry>
        <mesh
          filename="package://scara/meshes/L1.STL" />
      </geometry>
      <material
        name="">
        <color
          rgba="0.79216 0.81961 0.93333 1" />
      </material>
    </visual>
    <collision>
      <origin
        xyz="0 0 0"
        rpy="0 0 0" />
      <geometry>
        <mesh
          filename="package://scara/meshes/L1.STL" />
      </geometry>
    </collision>
  </link>
  <joint
    name="J1"
    type="revolute">
    <origin
      xyz="0 0.035 0.13"
      rpy="1.5708 0 1.5708" />
    <parent
      link="base_link" />
    <child
      link="L1" />
    <axis
      xyz="0 1 0" />
    <limit
      lower="-3.141"
      upper="3.141"
      effort="5"
      velocity="1" />
  </joint>
  <link
    name="L2">
    <inertial>
      <origin
        xyz="0.065399 0.047234 -3.984E-08"
        rpy="0 0 0" />
      <mass
        value="0.76354" />
      <inertia
        ixx="0.00057749"
        ixy="8.8165E-05"
        ixz="-6.814E-10"
        iyy="0.0023115"
        iyz="8.1844E-10"
        izz="0.00252" />
    </inertial>
    <visual>
      <origin
        xyz="0 0 0"
        rpy="0 0 0" />
      <geometry>
        <mesh
          filename="package://scara/meshes/L2.STL" />
      </geometry>
      <material
        name="">
        <color
          rgba="0.79216 0.81961 0.93333 1" />
      </material>
    </visual>
    <collision>
      <origin
        xyz="0 0 0"
        rpy="0 0 0" />
      <geometry>
        <mesh
          filename="package://scara/meshes/L2.STL" />
      </geometry>
    </collision>
  </link>
  <joint
    name="J2"
    type="revolute">
    <origin
      xyz="0.14577 0.03 0"
      rpy="0 0 0" />
    <parent
      link="L1" />
    <child
      link="L2" />
    <axis
      xyz="0 1 0" />
    <limit
      lower="-3.141"
      upper="3.141"
      effort="5"
      velocity="1" />
  </joint>
  <link
    name="L3">
    <inertial>
      <origin
        xyz="5.5511E-17 -0.025 7.9337E-17"
        rpy="0 0 0" />
      <mass
        value="0.0088357" />
      <inertia
        ixx="2.4068E-06"
        ixy="-8.4801E-38"
        ixz="7.053E-38"
        iyy="1.1321E-06"
        iyz="-4.208E-22"
        izz="2.4068E-06" />
    </inertial>
    <visual>
      <origin
        xyz="0 0 0"
        rpy="0 0 0" />
      <geometry>
        <mesh
          filename="package://scara/meshes/L3.STL" />
      </geometry>
      <material
        name="">
        <color
          rgba="0.79216 0.81961 0.93333 1" />
      </material>
    </visual>
    <collision>
      <origin
        xyz="0 0 0"
        rpy="0 0 0" />
      <geometry>
        <mesh
          filename="package://scara/meshes/L3.STL" />
      </geometry>
    </collision>
  </link>
  <joint
    name="J3"
    type="revolute">
    <origin
      xyz="0.15 0.01 0"
      rpy="0 0 3.1416" />
    <parent
      link="L2" />
    <child
      link="L3" />
    <axis
      xyz="0 1 0" />
    <limit
      lower="-3.141"
      upper="3.141"
      effort="5"
      velocity="1" />
  </joint>
  <link
    name="L4">
    <inertial>
      <origin
        xyz="-2.7756E-16 0.06838 2.6195E-17"
        rpy="0 0 0" />
      <mass
        value="0.079259" />
      <inertia
        ixx="0.00031643"
        ixy="2.2941E-21"
        ixz="0"
        iyy="7.481E-06"
        iyz="-7.5439E-20"
        izz="0.00031643" />
    </inertial>
    <visual>
      <origin
        xyz="0 0 0"
        rpy="0 0 0" />
      <geometry>
        <mesh
          filename="package://scara/meshes/L4.STL" />
      </geometry>
      <material
        name="">
        <color
          rgba="0.79216 0.81961 0.93333 1" />
      </material>
    </visual>
    <collision>
      <origin
        xyz="0 0 0"
        rpy="0 0 0" />
      <geometry>
        <mesh
          filename="package://scara/meshes/L4.STL" />
      </geometry>
    </collision>
  </link>
  <joint
    name="J4"
    type="prismatic">
    <origin
      xyz="0 0 0"
      rpy="0 0 0" />
    <parent
      link="L3" />
    <child
      link="L4" />
    <axis
      xyz="0 1 0" />
    <limit
      lower="-0.12"
      upper="0"
      effort="5"
      velocity="1" />
  </joint>
</robot>