<?xml version="1.0" encoding="utf-8"?>
<!-- This URDF was automatically created by SolidWorks to URDF Exporter! Originally created by Stephen Brawner (brawner@gmail.com) 
     Commit Version: 1.6.0-4-g7f85cfe  Build Version: 1.6.7995.38578
     For more information, please see http://wiki.ros.org/sw_urdf_exporter -->
<robot
  name="station_robots">
  
<link name="base_link"/>

<joint name="scara_base_to_base_link" type="fixed">
    <origin xyz="3 0 0" rpy="0 0 0"/>
    <parent link="base_link"/>
    <child link="scara_base_link"/>
</joint>

<joint name="handler_base_to_base_link" type="fixed">
    <origin xyz="0 3 0" rpy="0 0 0"/> <!-- adjust xyz if needed -->
    <parent link="base_link"/>
    <child link="handler_base_link"/>
</joint>

<joint name="polisher_base_to_base_link" type="fixed">
    <origin xyz="3 3 0" rpy="0 0 0"/> <!-- adjust xyz if needed -->
    <parent link="base_link"/>
    <child link="polisher_base_link"/>
</joint>

<joint name="frame_to_base_link" type="fixed">
    <parent link="base_link"/>
    <child link="static_frame"/>
    <origin xyz="0 0 0" rpy="1.57 0 0"/>
</joint>




<link name="static_frame">
  <visual>
    <origin xyz="1.5 0 0" rpy="0 0 0"/>
    <geometry>
      <mesh filename="package://polishing_station/objects/meshes/machine.stl"/>
    </geometry>
    <material name="grey">
      <color rgba="0.5 0.5 0.5 1"/>
    </material>
  </visual>
  <collision>
    <origin xyz="1.5 0 0" rpy="0 0 0"/>
    <geometry>
      <mesh filename="package://polishing_station/objects/meshes/machine.stl"/>
    </geometry>
  </collision>
  <inertial>
    <mass value="10"/>
    <origin xyz="0 0 0" rpy="0 0 0"/>
    <inertia ixx="0.1" ixy="0" ixz="0" iyy="0.1" iyz="0" izz="0.1"/>
  </inertial>
</link>





  
  <link
    name="scara_base_link">
    <inertial>
      <origin
        xyz="4.9228E-19 0.057416 0.00026601"
        rpy="0 0 0" />
      <mass
        value="1.2659" />
      <inertia
        ixx="0.0041167"
        ixy="1.7022E-19"
        ixz="-1.4674E-19"
        iyy="0.0027026"
        iyz="-2.6126E-05"
        izz="0.0031757" />
    </inertial>
    <visual>
      <origin
        xyz="0 0 0"
        rpy="0 0 0" />
      <geometry>
        <mesh
          filename="package://polishing_station/scara/meshes/base_link.STL" />
      </geometry>
      <material
        name="">
        <color
          rgba="0.79216 0.81961 0.93333 1" />
      </material>
    </visual>
    <collision>
      <origin
        xyz="0 0 0"
        rpy="0 0 0" />
      <geometry>
        <mesh
          filename="package://polishing_station/scara/meshes/base_link.STL" />
      </geometry>
    </collision>
  </link>
  <link
    name="scara_L1">
    <inertial>
      <origin
        xyz="0.067038 0.023797 -3.8903E-18"
        rpy="0 0 0" />
      <mass
        value="0.23993" />
      <inertia
        ixx="5.7474E-05"
        ixy="-5.325E-06"
        ixz="3.6951E-20"
        iyy="0.00068723"
        iyz="-2.0839E-21"
        izz="0.00066974" />
    </inertial>
    <visual>
      <origin
        xyz="0 0 0"
        rpy="0 0 0" />
      <geometry>
        <mesh
          filename="package://polishing_station/scara/meshes/L1.STL" />
      </geometry>
      <material
        name="">
        <color
          rgba="0.79216 0.81961 0.93333 1" />
      </material>
    </visual>
    <collision>
      <origin
        xyz="0 0 0"
        rpy="0 0 0" />
      <geometry>
        <mesh
          filename="package://polishing_station/scara/meshes/L1.STL" />
      </geometry>
    </collision>
  </link>
  <joint
    name="scara_J1"
    type="revolute">
    <origin
      xyz="0 0.035 0.13"
      rpy="1.5708 0 1.5708" />
    <parent
      link="scara_base_link" />
    <child
      link="scara_L1" />
    <axis
      xyz="0 1 0" />
    <limit
      lower="-3.141"
      upper="3.141"
      effort="5"
      velocity="1" />
  </joint>
  <link
    name="scara_L2">
    <inertial>
      <origin
        xyz="0.065399 0.047234 -3.984E-08"
        rpy="0 0 0" />
      <mass
        value="0.76354" />
      <inertia
        ixx="0.00057749"
        ixy="8.8165E-05"
        ixz="-6.814E-10"
        iyy="0.0023115"
        iyz="8.1844E-10"
        izz="0.00252" />
    </inertial>
    <visual>
      <origin
        xyz="0 0 0"
        rpy="0 0 0" />
      <geometry>
        <mesh
          filename="package://polishing_station/scara/meshes/L2.STL" />
      </geometry>
      <material
        name="">
        <color
          rgba="0.79216 0.81961 0.93333 1" />
      </material>
    </visual>
    <collision>
      <origin
        xyz="0 0 0"
        rpy="0 0 0" />
      <geometry>
        <mesh
          filename="package://polishing_station/scara/meshes/L2.STL" />
      </geometry>
    </collision>
  </link>
  <joint
    name="scara_J2"
    type="revolute">
    <origin
      xyz="0.14577 0.03 0"
      rpy="0 0 0" />
    <parent
      link="scara_L1" />
    <child
      link="scara_L2" />
    <axis
      xyz="0 1 0" />
    <limit
      lower="-3.141"
      upper="3.141"
      effort="5"
      velocity="1" />
  </joint>
  <link
    name="scara_L3">
    <inertial>
      <origin
        xyz="5.5511E-17 -0.025 7.9337E-17"
        rpy="0 0 0" />
      <mass
        value="0.0088357" />
      <inertia
        ixx="2.4068E-06"
        ixy="-8.4801E-38"
        ixz="7.053E-38"
        iyy="1.1321E-06"
        iyz="-4.208E-22"
        izz="2.4068E-06" />
    </inertial>
    <visual>
      <origin
        xyz="0 0 0"
        rpy="0 0 0" />
      <geometry>
        <mesh
          filename="package://polishing_station/scara/meshes/L3.STL" />
      </geometry>
      <material
        name="">
        <color
          rgba="0.79216 0.81961 0.93333 1" />
      </material>
    </visual>
    <collision>
      <origin
        xyz="0 0 0"
        rpy="0 0 0" />
      <geometry>
        <mesh
          filename="package://polishing_station/scara/meshes/L3.STL" />
      </geometry>
    </collision>
  </link>
  <joint
    name="scara_J3"
    type="revolute">
    <origin
      xyz="0.15 0.01 0"
      rpy="0 0 3.1416" />
    <parent
      link="scara_L2" />
    <child
      link="scara_L3" />
    <axis
      xyz="0 1 0" />
    <limit
      lower="-3.141"
      upper="3.141"
      effort="5"
      velocity="1" />
  </joint>
  <link
    name="scara_L4">
    <inertial>
      <origin
        xyz="-2.7756E-16 0.06838 2.6195E-17"
        rpy="0 0 0" />
      <mass
        value="0.079259" />
      <inertia
        ixx="0.00031643"
        ixy="2.2941E-21"
        ixz="0"
        iyy="7.481E-06"
        iyz="-7.5439E-20"
        izz="0.00031643" />
    </inertial>
    <visual>
      <origin
        xyz="0 0 0"
        rpy="0 0 0" />
      <geometry>
        <mesh
          filename="package://polishing_station/scara/meshes/L4.STL" />
      </geometry>
      <material
        name="">
        <color
          rgba="0.79216 0.81961 0.93333 1" />
      </material>
    </visual>
    <collision>
      <origin
        xyz="0 0 0"
        rpy="0 0 0" />
      <geometry>
        <mesh
          filename="package://polishing_station/scara/meshes/L4.STL" />
      </geometry>
    </collision>
  </link>
  <joint
    name="scara_J4"
    type="prismatic">
    <origin
      xyz="0 0 0"
      rpy="0 0 0" />
    <parent
      link="scara_L3" />
    <child
      link="scara_L4" />
    <axis
      xyz="0 1 0" />
    <limit
      lower="-0.12"
      upper="0"
      effort="5"
      velocity="1" />
  </joint>








  <link
    name="handler_base_link">
    <inertial>
      <origin
        xyz="2.988E-34 -0.017081 3.8741E-19"
        rpy="0 0 0" />
      <mass
        value="0.92342" />
      <inertia
        ixx="0.0014784"
        ixy="-1.0796E-35"
        ixz="1.5674E-35"
        iyy="0.0023047"
        iyz="-1.9374E-20"
        izz="0.0014784" />
    </inertial>
    <visual>
      <origin
        xyz="0 0 0"
        rpy="0 0 0" />
      <geometry>
        <mesh
          filename="package://polishing_station/handler/meshes/base_link.STL" />
      </geometry>
      <material
        name="">
        <color
          rgba="0.79216 0.81961 0.93333 1" />
      </material>
    </visual>
    <collision>
      <origin
        xyz="0 0 0"
        rpy="0 0 0" />
      <geometry>
        <mesh
          filename="package://polishing_station/handler/meshes/base_link.STL" />
      </geometry>
    </collision>
  </link>
  <link
    name="handler_L1">
    <inertial>
      <origin
        xyz="-0.010562 0.058034 2.1487E-08"
        rpy="0 0 0" />
      <mass
        value="2.1518" />
      <inertia
        ixx="0.0052232"
        ixy="0.0006223"
        ixz="-3.1183E-09"
        iyy="0.0067656"
        iyz="5.2126E-09"
        izz="0.0060009" />
    </inertial>
    <visual>
      <origin
        xyz="0 0 0"
        rpy="0 0 0" />
      <geometry>
        <mesh
          filename="package://polishing_station/handler/meshes/L1.STL" />
      </geometry>
      <material
        name="">
        <color
          rgba="0.79216 0.81961 0.93333 1" />
      </material>
    </visual>
    <collision>
      <origin
        xyz="0 0 0"
        rpy="0 0 0" />
      <geometry>
        <mesh
          filename="package://polishing_station/handler/meshes/L1.STL" />
      </geometry>
    </collision>
  </link>
  <joint
    name="handler_J1"
    type="revolute">
    <origin
      xyz="0 0 0.01"
      rpy="1.5708 0 0" />
    <parent
      link="handler_base_link" />
    <child
      link="handler_L1" />
    <axis
      xyz="0 1 0" />
    <limit
      lower="0"
      upper="0"
      effort="0"
      velocity="0" />
    <dynamics
      damping="1"
      friction="1" />
  </joint>
  <link
    name="handler_L2">
    <inertial>
      <origin
        xyz="0.059363 8.6014E-08 -0.19267"
        rpy="0 0 0" />
      <mass
        value="2.3432" />
      <inertia
        ixx="0.077054"
        ixy="4.3641E-10"
        ixz="0.00086007"
        iyy="0.077511"
        iyz="7.6816E-09"
        izz="0.0023404" />
    </inertial>
    <visual>
      <origin
        xyz="0 0 0"
        rpy="0 0 0" />
      <geometry>
        <mesh
          filename="package://polishing_station/handler/meshes/L2.STL" />
      </geometry>
      <material
        name="">
        <color
          rgba="0.79216 0.81961 0.93333 1" />
      </material>
    </visual>
    <collision>
      <origin
        xyz="0 0 0"
        rpy="0 0 0" />
      <geometry>
        <mesh
          filename="package://polishing_station/handler/meshes/L2.STL" />
      </geometry>
    </collision>
  </link>
  <joint
    name="handler_J2"
    type="revolute">
    <origin
      xyz="-0.09 0.07 0"
      rpy="-1.5708 0 3.1416" />
    <parent
      link="handler_L1" />
    <child
      link="handler_L2" />
    <axis
      xyz="1 0 0" />
    <limit
      lower="0"
      upper="0"
      effort="0"
      velocity="0" />
    <dynamics
      damping="1"
      friction="1" />
  </joint>
  <link
    name="handler_L3">
    <inertial>
      <origin
        xyz="-0.029308 0.14601 -1.9972E-07"
        rpy="0 0 0" />
      <mass
        value="1.2035" />
      <inertia
        ixx="0.023041"
        ixy="0.0002755"
        ixz="5.9887E-09"
        iyy="0.00076928"
        iyz="6.6759E-09"
        izz="0.023199" />
    </inertial>
    <visual>
      <origin
        xyz="0 0 0"
        rpy="0 0 0" />
      <geometry>
        <mesh
          filename="package://polishing_station/handler/meshes/L3.STL" />
      </geometry>
      <material
        name="">
        <color
          rgba="0.79216 0.81961 0.93333 1" />
      </material>
    </visual>
    <collision>
      <origin
        xyz="0 0 0"
        rpy="0 0 0" />
      <geometry>
        <mesh
          filename="package://polishing_station/handler/meshes/L3.STL" />
      </geometry>
    </collision>
  </link>
  <joint
    name="handler_J3"
    type="revolute">
    <origin
      xyz="0 0 -0.45"
      rpy="-1.5708 0 0" />
    <parent
      link="handler_L2" />
    <child
      link="handler_L3" />
    <axis
      xyz="1 0 0" />
    <limit
      lower="0"
      upper="0"
      effort="0"
      velocity="0" />
    <dynamics
      damping="1"
      friction="1" />
  </joint>
  <link
    name="handler_L4">
    <inertial>
      <origin
        xyz="0.038122 -6.5766E-09 0.0090201"
        rpy="0 0 0" />
      <mass
        value="0.23425" />
      <inertia
        ixx="0.00015933"
        ixy="3.1181E-11"
        ixz="-3.9672E-06"
        iyy="0.00018421"
        iyz="-1.9002E-11"
        izz="0.0001233" />
    </inertial>
    <visual>
      <origin
        xyz="0 0 0"
        rpy="0 0 0" />
      <geometry>
        <mesh
          filename="package://polishing_station/handler/meshes/L4.STL" />
      </geometry>
      <material
        name="">
        <color
          rgba="0.79216 0.81961 0.93333 1" />
      </material>
    </visual>
    <collision>
      <origin
        xyz="0 0 0"
        rpy="0 0 0" />
      <geometry>
        <mesh
          filename="package://polishing_station/handler/meshes/L4.STL" />
      </geometry>
    </collision>
  </link>
  <joint
    name="handler_J4"
    type="revolute">
    <origin
      xyz="0 0.35 0"
      rpy="0 0 0" />
    <parent
      link="handler_L3" />
    <child
      link="handler_L4" />
    <axis
      xyz="1 0 0" />
    <limit
      lower="0"
      upper="0"
      effort="0"
      velocity="0" />
    <dynamics
      damping="1"
      friction="1" />
  </joint>
  <link
    name="handler_L5">
    <inertial>
      <origin
        xyz="0.027463 -8.8585E-09 -0.033154"
        rpy="0 0 0" />
      <mass
        value="0.20423" />
      <inertia
        ixx="6.697E-05"
        ixy="-1.8659E-10"
        ixz="1.0354E-05"
        iyy="0.0002833"
        iyz="2.5719E-10"
        izz="0.00026912" />
    </inertial>
    <visual>
      <origin
        xyz="0 0 0"
        rpy="0 0 0" />
      <geometry>
        <mesh
          filename="package://polishing_station/handler/meshes/L5.STL" />
      </geometry>
      <material
        name="">
        <color
          rgba="0.79216 0.81961 0.93333 1" />
      </material>
    </visual>
    <collision>
      <origin
        xyz="0 0 0"
        rpy="0 0 0" />
      <geometry>
        <mesh
          filename="package://polishing_station/handler/meshes/L5.STL" />
      </geometry>
    </collision>
  </link>
  <joint
    name="handler_J5"
    type="revolute">
    <origin
      xyz="0.04 0 0.05"
      rpy="3.1416 0 1.5708" />
    <parent
      link="handler_L4" />
    <child
      link="handler_L5" />
    <axis
      xyz="0 0 1" />
    <limit
      lower="0"
      upper="0"
      effort="0"
      velocity="0" />
    <dynamics
      damping="1"
      friction="1" />
  </joint>
  <link
    name="handler_L6">
    <inertial>
      <origin
        xyz="-1.3878E-17 0.01201 8.3267E-17"
        rpy="0 0 0" />
      <mass
        value="0.02287" />
      <inertia
        ixx="3.033E-06"
        ixy="2.7708E-22"
        ixz="6.3545E-37"
        iyy="3.6242E-06"
        iyz="7.5673E-22"
        izz="3.033E-06" />
    </inertial>
    <visual>
      <origin
        xyz="0 0 0"
        rpy="0 0 0" />
      <geometry>
        <mesh
          filename="package://polishing_station/handler/meshes/L6.STL" />
      </geometry>
      <material
        name="">
        <color
          rgba="0.79216 0.81961 0.93333 1" />
      </material>
    </visual>
    <collision>
      <origin
        xyz="0 0 0"
        rpy="0 0 0" />
      <geometry>
        <mesh
          filename="package://polishing_station/handler/meshes/L6.STL" />
      </geometry>
    </collision>
  </link>
  <joint
    name="handler_J6"
    type="revolute">
    <origin
      xyz="0.095 0 -0.035"
      rpy="1.5708 1.5708 0" />
    <parent
      link="handler_L5" />
    <child
      link="handler_L6" />
    <axis
      xyz="0 1 0" />
    <limit
      lower="0"
      upper="0"
      effort="0"
      velocity="0" />
    <dynamics
      damping="1"
      friction="1" />
  </joint>



<link
    name="polisher_base_link">
    <inertial>
      <origin
        xyz="1.1824E-34 0.0020988 -8.1451E-18"
        rpy="0 0 0" />
      <mass
        value="0.50894" />
      <inertia
        ixx="0.001056"
        ixy="-2.9324E-36"
        ixz="7.2641E-36"
        iyy="0.0020612"
        iyz="2.0746E-20"
        izz="0.001056" />
    </inertial>
    <visual>
      <origin
        xyz="0 0 0"
        rpy="0 0 0" />
      <geometry>
        <mesh
          filename="package://polishing_station/polisher/meshes/base_link.STL" />
      </geometry>
      <material
        name="">
        <color
          rgba="0.79216 0.81961 0.93333 1" />
      </material>
    </visual>
    <collision>
      <origin
        xyz="0 0 0"
        rpy="0 0 0" />
      <geometry>
        <mesh
          filename="package://polishing_station/polisher/meshes/base_link.STL" />
      </geometry>
    </collision>
  </link>
  <link
    name="polisher_L1">
    <inertial>
      <origin
        xyz="2.609E-07 0.069404 3.3533E-08"
        rpy="0 0 0" />
      <mass
        value="2.6203" />
      <inertia
        ixx="0.01468"
        ixy="-4.4372E-08"
        ixz="-6.9928E-10"
        iyy="0.011798"
        iyz="-7.3338E-10"
        izz="0.011038" />
    </inertial>
    <visual>
      <origin
        xyz="0 0 0"
        rpy="0 0 0" />
      <geometry>
        <mesh
          filename="package://polishing_station/polisher/meshes/L1.STL" />
      </geometry>
      <material
        name="">
        <color
          rgba="0.79216 0.81961 0.93333 1" />
      </material>
    </visual>
    <collision>
      <origin
        xyz="0 0 0"
        rpy="0 0 0" />
      <geometry>
        <mesh
          filename="package://polishing_station/polisher/meshes/L1.STL" />
      </geometry>
    </collision>
  </link>
  <joint
    name="polisher_J1"
    type="revolute">
    <origin
      xyz="0 0 0.01"
      rpy="1.5708 0 0" />
    <parent
      link="polisher_base_link" />
    <child
      link="polisher_L1" />
    <axis
      xyz="0 1 0" />
    <limit
      lower="-3.141"
      upper="3.141"
      effort="5"
      velocity="1" />
  </joint>
  <link
    name="polisher_L2">
    <inertial>
      <origin
        xyz="2.5758E-09 -2.0066E-08 -0.17282"
        rpy="0 0 0" />
      <mass
        value="3.6365" />
      <inertia
        ixx="0.077736"
        ixy="-1.0778E-10"
        ixz="-4.0562E-10"
        iyy="0.078819"
        iyz="1.4721E-08"
        izz="0.0059647" />
    </inertial>
    <visual>
      <origin
        xyz="0 0 0"
        rpy="0 0 0" />
      <geometry>
        <mesh
          filename="package://polishing_station/polisher/meshes/L2.STL" />
      </geometry>
      <material
        name="">
        <color
          rgba="0.79216 0.81961 0.93333 1" />
      </material>
    </visual>
    <collision>
      <origin
        xyz="0 0 0"
        rpy="0 0 0" />
      <geometry>
        <mesh
          filename="package://polishing_station/polisher/meshes/L2.STL" />
      </geometry>
    </collision>
  </link>
  <joint
    name="polisher_J2"
    type="revolute">
    <origin
      xyz="0 0.13062 0"
      rpy="1.5708 -1.5708 0" />
    <parent
      link="polisher_L1" />
    <child
      link="polisher_L2" />
    <axis
      xyz="1 0 0" />
    <limit
      lower="-3.141"
      upper="3.141"
      effort="5"
      velocity="1" />
  </joint>
  <link
    name="polisher_L3">
    <inertial>
      <origin
        xyz="0.01 7.4465E-08 -0.11079"
        rpy="0 0 0" />
      <mass
        value="2.2512" />
      <inertia
        ixx="0.019258"
        ixy="-2.3005E-09"
        ixz="4.644E-09"
        iyy="0.020386"
        iyz="1.9429E-09"
        izz="0.0030744" />
    </inertial>
    <visual>
      <origin
        xyz="0 0 0"
        rpy="0 0 0" />
      <geometry>
        <mesh
          filename="package://polishing_station/polisher/meshes/L3.STL" />
      </geometry>
      <material
        name="">
        <color
          rgba="0.79216 0.81961 0.93333 1" />
      </material>
    </visual>
    <collision>
      <origin
        xyz="0 0 0"
        rpy="0 0 0" />
      <geometry>
        <mesh
          filename="package://polishing_station/polisher/meshes/L3.STL" />
      </geometry>
    </collision>
  </link>
  <joint
    name="polisher_J3"
    type="revolute">
    <origin
      xyz="0 0 -0.425"
      rpy="0 0 -3.1416" />
    <parent
      link="polisher_L2" />
    <child
      link="polisher_L3" />
    <axis
      xyz="1 0 0" />
    <limit
      lower="-3.141"
      upper="3.141"
      effort="5"
      velocity="1" />
  </joint>
  <link
    name="polisher_L4">
    <inertial>
      <origin
        xyz="-0.01 5.9649E-08 -0.0081105"
        rpy="0 0 0" />
      <mass
        value="0.22465" />
      <inertia
        ixx="0.00012689"
        ixy="-1.3381E-10"
        ixz="-6.8739E-12"
        iyy="0.00017646"
        iyz="7.2481E-11"
        izz="0.00013362" />
    </inertial>
    <visual>
      <origin
        xyz="0 0 0"
        rpy="0 0 0" />
      <geometry>
        <mesh
          filename="package://polishing_station/polisher/meshes/L4.STL" />
      </geometry>
      <material
        name="">
        <color
          rgba="0.79216 0.81961 0.93333 1" />
      </material>
    </visual>
    <collision>
      <origin
        xyz="0 0 0"
        rpy="0 0 0" />
      <geometry>
        <mesh
          filename="package://polishing_station/polisher/meshes/L4.STL" />
      </geometry>
    </collision>
  </link>
  <joint
    name="polisher_J4"
    type="revolute">
    <origin
      xyz="0 0 -0.3"
      rpy="0 0 3.1416" />
    <parent
      link="polisher_L3" />
    <child
      link="polisher_L4" />
    <axis
      xyz="1 0 0" />
    <limit
      lower="-3.141"
      upper="3.141"
      effort="5"
      velocity="1" />
  </joint>
  <link
    name="polisher_L5">
    <inertial>
      <origin
        xyz="1.2143E-17 -4.5869E-16 -0.058396"
        rpy="0 0 0" />
      <mass
        value="0.16928" />
      <inertia
        ixx="0.00020457"
        ixy="8.4957E-21"
        ixz="1.5658E-20"
        iyy="0.00020457"
        iyz="3.1565E-21"
        izz="0.00010248" />
    </inertial>
    <visual>
      <origin
        xyz="0 0 0"
        rpy="0 0 0" />
      <geometry>
        <mesh
          filename="package://polishing_station/polisher/meshes/L5.STL" />
      </geometry>
      <material
        name="">
        <color
          rgba="0.79216 0.81961 0.93333 1" />
      </material>
    </visual>
    <collision>
      <origin
        xyz="0 0 0"
        rpy="0 0 0" />
      <geometry>
        <mesh
          filename="package://polishing_station/polisher/meshes/L5.STL" />
      </geometry>
    </collision>
  </link>
  <joint
    name="polisher_J5"
    type="revolute">
    <origin
      xyz="-0.01 0 -0.045"
      rpy="0 0 -3.1416" />
    <parent
      link="polisher_L4" />
    <child
      link="polisher_L5" />
    <axis
      xyz="0 0 1" />
    <limit
      lower="-3.141"
      upper="3.141"
      effort="5"
      velocity="1" />
  </joint>


</robot>