<?xml version="1.0" encoding="utf-8" ?>
<!-- This URDF was automatically created by SolidWorks to URDF Exporter! Originally created by Stephen Brawner (brawner@gmail.com) 
     Commit Version: 1.6.0-4-g7f85cfe  Build Version: 1.6.7995.38578
     For more information, please see http://wiki.ros.org/sw_urdf_exporter -->
<robot name="handler">
    <link name="base_link">
        <inertial>
            <origin xyz="2.988E-34 -0.017081 3.8741E-19" rpy="0 0 0" />
            <mass value="0.92342" />
            <inertia ixx="0.0014784" ixy="-1.0796E-35" ixz="1.5674E-35" iyy="0.0023047" iyz="-1.9374E-20" izz="0.0014784" />
        </inertial>
        <visual>
            <origin xyz="0 0 0" rpy="0 0 0" />
            <geometry>
                <mesh filename="package://handler/meshes/base_link.STL" />
            </geometry>
            <material name="">
                <color rgba="0.79216 0.81961 0.93333 1" />
            </material>
        </visual>
        <collision>
            <origin xyz="0 0 0" rpy="0 0 0" />
            <geometry>
                <mesh filename="package://handler/meshes/base_link.STL" />
            </geometry>
        </collision>
    </link>
    <link name="L1">
        <inertial>
            <origin xyz="-0.010562 0.058034 2.1487E-08" rpy="0 0 0" />
            <mass value="2.1518" />
            <inertia ixx="0.0052232" ixy="0.0006223" ixz="-3.1183E-09" iyy="0.0067656" iyz="5.2126E-09" izz="0.0060009" />
        </inertial>
        <visual>
            <origin xyz="0 0 0" rpy="0 0 0" />
            <geometry>
                <mesh filename="package://handler/meshes/L1.STL" />
            </geometry>
            <material name="">
                <color rgba="0.79216 0.81961 0.93333 1" />
            </material>
        </visual>
        <collision>
            <origin xyz="0 0 0" rpy="0 0 0" />
            <geometry>
                <mesh filename="package://handler/meshes/L1.STL" />
            </geometry>
        </collision>
    </link>
    <joint name="J1" type="revolute">
        <origin xyz="0 0 0.01" rpy="1.5708 0 0" />
        <parent link="base_link" />
        <child link="L1" />
        <axis xyz="0 1 0" />
        <limit lower="-1.57" upper="1.57" effort="5" velocity="1" />
        <dynamics damping="1" friction="1" />
    </joint>
    <link name="L2">
        <inertial>
            <origin xyz="0.059363 8.6014E-08 -0.19267" rpy="0 0 0" />
            <mass value="2.3432" />
            <inertia ixx="0.077054" ixy="4.3641E-10" ixz="0.00086007" iyy="0.077511" iyz="7.6816E-09" izz="0.0023404" />
        </inertial>
        <visual>
            <origin xyz="0 0 0" rpy="0 0 0" />
            <geometry>
                <mesh filename="package://handler/meshes/L2.STL" />
            </geometry>
            <material name="">
                <color rgba="0.79216 0.81961 0.93333 1" />
            </material>
        </visual>
        <collision>
            <origin xyz="0 0 0" rpy="0 0 0" />
            <geometry>
                <mesh filename="package://handler/meshes/L2.STL" />
            </geometry>
        </collision>
    </link>
    <joint name="J2" type="revolute">
        <origin xyz="-0.09 0.07 0" rpy="-1.5708 0 3.1416" />
        <parent link="L1" />
        <child link="L2" />
        <axis xyz="1 0 0" />
        <limit lower="-1.57" upper="1.57" effort="5" velocity="1" />
        <dynamics damping="1" friction="1" />
    </joint>
    <link name="L3">
        <inertial>
            <origin xyz="-0.029308 0.14601 -1.9972E-07" rpy="0 0 0" />
            <mass value="1.2035" />
            <inertia ixx="0.023041" ixy="0.0002755" ixz="5.9887E-09" iyy="0.00076928" iyz="6.6759E-09" izz="0.023199" />
        </inertial>
        <visual>
            <origin xyz="0 0 0" rpy="0 0 0" />
            <geometry>
                <mesh filename="package://handler/meshes/L3.STL" />
            </geometry>
            <material name="">
                <color rgba="0.79216 0.81961 0.93333 1" />
            </material>
        </visual>
        <collision>
            <origin xyz="0 0 0" rpy="0 0 0" />
            <geometry>
                <mesh filename="package://handler/meshes/L3.STL" />
            </geometry>
        </collision>
    </link>
    <joint name="J3" type="revolute">
        <origin xyz="0 0 -0.45" rpy="-1.5708 0 0" />
        <parent link="L2" />
        <child link="L3" />
        <axis xyz="1 0 0" />
        <limit lower="-1.57" upper="1.57" effort="5" velocity="1" />
        <dynamics damping="1" friction="1" />
    </joint>
    <link name="L4">
        <inertial>
            <origin xyz="0.038122 -6.5766E-09 0.0090201" rpy="0 0 0" />
            <mass value="0.23425" />
            <inertia ixx="0.00015933" ixy="3.1181E-11" ixz="-3.9672E-06" iyy="0.00018421" iyz="-1.9002E-11" izz="0.0001233" />
        </inertial>
        <visual>
            <origin xyz="0 0 0" rpy="0 0 0" />
            <geometry>
                <mesh filename="package://handler/meshes/L4.STL" />
            </geometry>
            <material name="">
                <color rgba="0.79216 0.81961 0.93333 1" />
            </material>
        </visual>
        <collision>
            <origin xyz="0 0 0" rpy="0 0 0" />
            <geometry>
                <mesh filename="package://handler/meshes/L4.STL" />
            </geometry>
        </collision>
    </link>
    <joint name="J4" type="revolute">
        <origin xyz="0 0.35 0" rpy="0 0 0" />
        <parent link="L3" />
        <child link="L4" />
        <axis xyz="1 0 0" />
        <limit lower="-1.57" upper="1.57" effort="5" velocity="1" />
        <dynamics damping="1" friction="1" />
    </joint>
    <link name="L5">
        <inertial>
            <origin xyz="0.027463 -8.8585E-09 -0.033154" rpy="0 0 0" />
            <mass value="0.20423" />
            <inertia ixx="6.697E-05" ixy="-1.8659E-10" ixz="1.0354E-05" iyy="0.0002833" iyz="2.5719E-10" izz="0.00026912" />
        </inertial>
        <visual>
            <origin xyz="0 0 0" rpy="0 0 0" />
            <geometry>
                <mesh filename="package://handler/meshes/L5.STL" />
            </geometry>
            <material name="">
                <color rgba="0.79216 0.81961 0.93333 1" />
            </material>
        </visual>
        <collision>
            <origin xyz="0 0 0" rpy="0 0 0" />
            <geometry>
                <mesh filename="package://handler/meshes/L5.STL" />
            </geometry>
        </collision>
    </link>
    <joint name="J5" type="revolute">
        <origin xyz="0.04 0 0.05" rpy="3.1416 0 1.5708" />
        <parent link="L4" />
        <child link="L5" />
        <axis xyz="0 0 1" />
        <limit lower="-1.57" upper="1.57" effort="5" velocity="1" />
        <dynamics damping="1" friction="1" />
    </joint>
    <link name="L6">
        <inertial>
            <origin xyz="-1.3878E-17 0.01201 8.3267E-17" rpy="0 0 0" />
            <mass value="0.02287" />
            <inertia ixx="3.033E-06" ixy="2.7708E-22" ixz="6.3545E-37" iyy="3.6242E-06" iyz="7.5673E-22" izz="3.033E-06" />
        </inertial>
        <visual>
            <origin xyz="0 0 0" rpy="0 0 0" />
            <geometry>
                <mesh filename="package://handler/meshes/L6.STL" />
            </geometry>
            <material name="">
                <color rgba="0.79216 0.81961 0.93333 1" />
            </material>
        </visual>
        <collision>
            <origin xyz="0 0 0" rpy="0 0 0" />
            <geometry>
                <mesh filename="package://handler/meshes/L6.STL" />
            </geometry>
        </collision>
    </link>
    <joint name="J6" type="revolute">
        <origin xyz="0.095 0 -0.035" rpy="1.5708 1.5708 0" />
        <parent link="L5" />
        <child link="L6" />
        <axis xyz="0 1 0" />
        <limit lower="-1.57" upper="1.57" effort="5" velocity="1" />
        <dynamics damping="1" friction="1" />
    </joint>
    <transmission name="trans_J1">
        <type>transmission_interface/SimpleTransmission</type>
        <joint name="J1">
            <hardwareInterface>hardware_interface/PositionJointInterface</hardwareInterface>
        </joint>
        <actuator name="J1_motor">
            <hardwareInterface>hardware_interface/PositionJointInterface</hardwareInterface>
            <mechanicalReduction>1</mechanicalReduction>
        </actuator>
    </transmission>
    <transmission name="trans_J2">
        <type>transmission_interface/SimpleTransmission</type>
        <joint name="J2">
            <hardwareInterface>hardware_interface/PositionJointInterface</hardwareInterface>
        </joint>
        <actuator name="J2_motor">
            <hardwareInterface>hardware_interface/PositionJointInterface</hardwareInterface>
            <mechanicalReduction>1</mechanicalReduction>
        </actuator>
    </transmission>
    <transmission name="trans_J3">
        <type>transmission_interface/SimpleTransmission</type>
        <joint name="J3">
            <hardwareInterface>hardware_interface/PositionJointInterface</hardwareInterface>
        </joint>
        <actuator name="J3_motor">
            <hardwareInterface>hardware_interface/PositionJointInterface</hardwareInterface>
            <mechanicalReduction>1</mechanicalReduction>
        </actuator>
    </transmission>
    <transmission name="trans_J4">
        <type>transmission_interface/SimpleTransmission</type>
        <joint name="J4">
            <hardwareInterface>hardware_interface/PositionJointInterface</hardwareInterface>
        </joint>
        <actuator name="J4_motor">
            <hardwareInterface>hardware_interface/PositionJointInterface</hardwareInterface>
            <mechanicalReduction>1</mechanicalReduction>
        </actuator>
    </transmission>
    <transmission name="trans_J5">
        <type>transmission_interface/SimpleTransmission</type>
        <joint name="J5">
            <hardwareInterface>hardware_interface/PositionJointInterface</hardwareInterface>
        </joint>
        <actuator name="J5_motor">
            <hardwareInterface>hardware_interface/PositionJointInterface</hardwareInterface>
            <mechanicalReduction>1</mechanicalReduction>
        </actuator>
    </transmission>
    <transmission name="trans_J6">
        <type>transmission_interface/SimpleTransmission</type>
        <joint name="J6">
            <hardwareInterface>hardware_interface/PositionJointInterface</hardwareInterface>
        </joint>
        <actuator name="J6_motor">
            <hardwareInterface>hardware_interface/PositionJointInterface</hardwareInterface>
            <mechanicalReduction>1</mechanicalReduction>
        </actuator>
    </transmission>
    <gazebo>
        <plugin name="control" filename = "libgazebo_ros_control">
        </plugin>
    </gazebo>
    <gazebo>
      <plugin name = "joint_state_publisher" filename = "libgazebo_ros_joint_state_publisher.so">
      <jointName>J1, J2, J3, J4, J5 ,J6 </jointName>
      </plugin>
    </gazebo>
</robot>

